<?xml version="1.0"?>
<robot name="mapping_demonstrator" xmlns:xacro="http://ros.org/wiki/xacro">
<property name="M_PI" value="3.14159"/>
<xacro:macro name="map_demo">

	<link name="map"/>
	<!-- BASE LINK is the lower case-->
	<link name="base"/>
			<!--inertial>
				<origin xyz="0 0 0" rpy="0 0 0"/>
				<mass value="0.1"/>
				<inertia ixx="0.01" ixy="0" ixz="0" iyy="0.01" iyz="0" izz="0.01" />
			</inertial-->

		<!--visual>
			<origin xyz="0 0 0.05" rpy="0 0 0" />
			<geometry>
				<box size= "0.45 0.385 0.140"/>
			</geometry>
			<material name="white">
				<color rgba="0.85 0.85 0.85 1"/>
			</material>
		</visual-->

			<!--collision>
				<origin xyz="0 0 0" rpy="0 0 0" />
				<geometry>
					<box xyz= "0 0 0"/>
				</geometry>
			</collision-->
		<!--/link-->

	<!--link name="pole">
		<visual>
			<origin xyz="0 0 0.140" rpy="0 0 0" />
			<geometry>
				<box size= "0.045 0.045 1.1"/>
			</geometry>
			<material name="white">
				<color rgba="0.65 0.65 0.65 1"/>
			</material>
		</visual>
	</link>
	-->
	<!--link name="topstruct">
		<visual>
			<origin xyz="0 0 1.10" rpy="0 0 0" />
			<geometry>
				<box size= "0.05 0.05 0.13"/>
			</geometry>
			<material name="bluish">
				<color rgba="0.35 0.55 0.85 1"/>
			</material>
		</visual>
	</link>
	-->
	<link name="pan"/>
				<!--inertial>
			<origin xyz="0 0 0" rpy="0 0 0"/>
			<mass value="0.1"/>
			<inertia ixx="0.01" ixy="0" ixz="0" iyy="0.01" iyz="0" izz="0.01" />
		</inertial-->

		<!--visual>
			<origin xyz="0 0 1.10" rpy="0 0 -3.14" />
			<geometry>
				<box size= "0.045 0.045 0.64"/>
			</geometry>
			<material name="grey">
				<color rgba="0.95 0.75 0.10 1"/>
			</material>
		</visual>

			<collision>
				<origin xyz="0 0 0" rpy="0 0 0" />
				<geometry>
					<box xyz= "0 0 0"/>
				</geometry>
			</collision>
		</link>
		-->
		<link name="tilt"/>
		<!--link name="camera_link"/-->
			<!--inertial>
				<origin xyz="0 0 0" rpy="0 0 0"/>
				<mass value="0.1"/>
				<inertia ixx="0.01" ixy="0" ixz="0" iyy="0.01" iyz="0" izz="0.01" />
			</inertial-->

			<!--visual>
				<origin xyz="0 0 1.14" rpy="1.57 0 0" />
				<geometry>
					<box size= "0.045 0.045 0.5"/>
				</geometry>
				<material name="grey" />
					<color rgba="0.25 0.25 0.50 1"/>
				</material>
			</visual>

			<collision>
				<origin xyz="0 0 0" rpy="0 0 0" />
				<geometry>
					<box xyz= "0 0 0"/>
				</geometry>
			</collision-->
		<!--/link-->
		<!--link name="kinect">
			<inertial>
				<origin xyz="0 0 0" rpy="0 0 0"/>
				<mass value="0.1"/>
				<inertia ixx="0.01" ixy="0" ixz="0" iyy="0.01" iyz="0" izz="0.01" />
			</inertial-->

			<!--visual>
				<origin xyz="0 0 1.44" rpy="0 0 0" />
				<geometry>
					<box size= "0.18 0.05 0.2"/>
				</geometry>
				<material name="Yellow" />
					<color rgba="0.65 0.95 0.30 1"/>
				</material>
			</visual>

			<collision>
				<origin xyz="0 0 0" rpy="0 0 0" />
				<geometry>
					<box xyz= "0 0 0"/>
				</geometry>
			</collision-->
		<!--/link-->
		<joint name="map_base" type="fixed">
			<parent link="map"/>
			<child link="base" />
			<origin xyz="0 0 0" rpy="0 0 0"/>
		</joint>
		<joint name="servo_pan" type="revolute">
			<parent link="base"/>
			<child link="pan" />
			<origin xyz="0 0 1.42" rpy="0 3.14 0"/>
			<limit lower="-1.57" upper="1.57" velocity="1.0" effort="0"/>
			<!--calibration rising="-0.9"/-->
			<calibration rising="0"/>
			<!-- max vel is 5.23 -->
			<axis xyz="0 0 1"/>
		</joint>

		<joint name="servo_tilt" type="revolute">
			<parent link="pan"/>
			<child link="tilt"/>
			<origin xyz="0 0 -0.02" rpy="-1.57 0 0"/>
			<axis xyz="0 0 1"/>
			<limit lower="-1.05" upper="1.05" velocity="1.0" effort="0"/>
			<!-- max vel is 12.31-->
			<!--calibration rising="0.04"/-->
			<calibration rising="0"/>
			<!--max vel is 12.32 -->
		</joint>

		<joint name="camjoint" type="fixed">
			<parent link="tilt"/>
			<child link="camera_link"/>
			<origin xyz="0 0.068 0.0" rpy="-1.57 0 0"/>
		</joint>

		  <!--joint name="base_camera_joint" type="fixed">
    <origin xyz="${turtlebot_calib_cam_x} ${turtlebot_calib_cam_y} 0.124"
            rpy="${turtlebot_calib_cam_rr} ${turtlebot_calib_cam_rp} ${turtlebot_calib_cam_ry}" />
    <parent link="${turtlebot_camera_parent_name}" />
    <child link="camera_link" />
  </joint-->
  <link name="camera_link">
    <inertial>
      <mass value="0.01" />
      <origin xyz="0 0 0" />
      <inertia ixx="0.001" ixy="0.0" ixz="0.0"
        iyy="0.001" iyz="0.0"
        izz="0.001" />
    </inertial>
    <visual>
      <origin xyz=" 0 0 0 " rpy="0 0 0" />
      <geometry>
        <mesh filename="package://turtlebot_description/meshes/kinect.dae"/>
      </geometry>
    </visual>
    <collision>
      <origin xyz="0.0 0.0 0.0" rpy="0 0 0" />
      <geometry>
        <box size="0.0730 .2760 0.0720"/>
      </geometry>
    </collision>
  </link>
  <joint name="camera_depth_joint" type="fixed">
    <origin xyz="0 0.049 0" rpy="0 0 0" />
    <parent link="camera_link" />
    <child link="camera_depth_frame" />
  </joint>
  <link name="camera_depth_frame">
    <inertial>
      <mass value="0.01" />
      <origin xyz="0 0 0" />
      <inertia ixx="0.001" ixy="0.0" ixz="0.0"
        iyy="0.001" iyz="0.0"
        izz="0.001" />
    </inertial>
  </link>
  <joint name="camera_depth_optical_joint" type="fixed">
    <origin xyz="0 0 0" rpy="${-M_PI/2} 0 ${-M_PI/2}" />
    <parent link="camera_depth_frame" />
    <child link="camera_depth_optical_frame" />
  </joint>
  <link name="camera_depth_optical_frame">
    <inertial>
      <mass value="0.001" />
      <origin xyz="0 0 0" />
      <inertia ixx="0.0001" ixy="0.0" ixz="0.0"
        iyy="0.0001" iyz="0.0"
        izz="0.0001" />
    </inertial>
  </link>
  <joint name="camera_rgb_joint" type="fixed">
    <origin xyz="0 0.022 0" rpy="0 0 0" />
    <parent link="camera_link" />
    <child link="camera_rgb_frame" />
  </joint>
  <link name="camera_rgb_frame">
    <inertial>
      <mass value="0.001" />
      <origin xyz="0 0 0" />
      <inertia ixx="0.0001" ixy="0.0" ixz="0.0"
        iyy="0.0001" iyz="0.0"
        izz="0.0001" />
    </inertial>
  </link>
  <joint name="camera_rgb_optical_joint" type="fixed">
    <origin xyz="0 0 0" rpy="${-M_PI/2} 0 ${-M_PI/2}" />
    <parent link="camera_rgb_frame" />
    <child link="camera_rgb_optical_frame" />
  </joint>
  <link name="camera_rgb_optical_frame">
    <inertial>
      <mass value="0.001" />
      <origin xyz="0 0 0" />
      <inertia ixx="0.0001" ixy="0.0" ixz="0.0"
        iyy="0.0001" iyz="0.0"
        izz="0.0001" />
    </inertial>
  </link>

</xacro:macro>
<xacro:map_demo/>
</robot>
